Workbook

Sheet 报关单
A1: 中华人民共和国海关出口货物报关单
A2: 预录入编号： | F2: 申报口岸: | I2: 海关编号:
A3: 境内发货人 | E3: 出境关别 | F3: ( 大鹏海关 ) | G3: 出口日期 | K3: 申报日期 | O3: 备案号 | U3: 签约地点： | V3: 深圳
A4: 深圳市新棱镜贸易有限公司 | U4: 成交方式: | V4: =I12 -> FOB | W4: SHENZHEN | X4: 付款条件： | Y4: 电汇 先出后结
A5: 境外收货人 | C5: AEO： | E5: 运输方式 | F5: ( ) | G5: 运输工具名称及航次号 | K5: 提运单号 | U5: 卖方公司： | V5: =A4 -> 深圳市新棱镜贸易有限公司
A6: HONG KONG YUN QI LIAN TECHNOLOGY LIMITED | E6: 水路运输 | U6: 卖方地址： | V6: 1702, Block C, Rongchuang Zhihui Building, Longhua District, Shenzhen City, China.
A7: 生产销售单位 | C7: =C3 -> 0 | E7: 监管方式 | F7: ( ) | G7: 征免性质 | H7: ( ) | K7: 许可证号 | U7: 卖方电话： | V7: 18823202180 | X7: 卖方传真：
A8: 深圳市新棱镜贸易有限公司 | E8: 一般贸易 | G8: 一般征税 | U8: 买方公司： | V8: HONG KONG YUN QI LIAN TECHNOLOGY LIMITED
A9: 合同协议号 | E9: 贸易国(地区) | F9: ( ) | G9: 运抵国(地区) | H9: ( ) | K9: 指运港 | L9: ( ) | O9: 离境口岸 | P9: ( )跨境的才需要申报 | U9: 买方地址： | V9: RM 10, 23/F NEW TREND CTR NO704 PRINCE EDWARD RD EAST SANPO KONGHONG KONG
A10: 2026011202 | E10: 香港 | G10: 英国 | U10: 买方电话： | V10: 13071079299 | X10: 买方传真：
A11: 包装种类 | C11: ( 纸箱 ) | E11: 件数 | F11: 毛重（千克） | G11: 净重（千克） | I11: 成交方式 | J11: ( ) | K11: 运费 | N11: 保费 | Q11: 杂费 | U11: 报关简称： | X11: 报关全称：
E12: =V18 -> 2 | F12: =U18 -> 39.3 | G12: =T18 -> 36 | I12: FOB | T12: 境外收货人： | W12: 境外收货人通常指签订并执行出口贸易合同中的买方或合同指定的收货人，名称一般填报英文名称，检验检疫要求填报其他外文名称的，在英文名称后填报，以半角括号分隔。
A13: 随附单证及编号 | T13: 境外收货人代码： | W13: 非互认国家（地区）AEO企业等其他情形，编码免于填报。对于AEO互认国家（地区）企业的，编码填报AEO编码，填报样式按照海关总署发布的相关公告要求填报（如新加坡AEO企业填报样式为：SG123456789012，韩国AEO企业填报样式为KR1234567，具体见相关公告要求）。
A14: 境外收货人完整显示： | D14: =A6 -> HONG KONG YUN QI LIAN TECHNOLOGY LIMITED | T14: 检验检疫附加编号： | W14: 通过以下网站输入10位HS编号，再根据申报要素细分确定3位检疫附加编号
A15: 标记唛码及备注： | C15: 退税 | T15: 检疫局网址-编码查询： | W15: https://e-service.shciq.gov.cn/shesp/
A16: 备注： | T16: 查申报要素网址： | W16: http://www.hscode.net/IntegrateQueries/QueryYS/
L17: 报关联系电话： | T17: 合计： | W17: 贸易国：出口是指合同买方所在的国家（地区），需填写准确，以后可能会影响收汇。
A18: 特殊关系确认: | D18: 价格影响确认： | F18: 支付特许权使用费: | I18: 自报自缴: | K18: 出口不填 | L18: 原产国/目的国/货源地未注明的项默认与提供的项相同 | T18: =SUM(T20:T483) -> 36 | U18: =SUM(U20:U483) -> 39.3 | V18: =SUM(V20:V483) -> 2
A19: 项号 | B19: 商品编号 | D19: 商品名称及规格型号 | G19: 数量及单位 | I19: 单价/总价/币制 | K19: 原产国（地区） | M19: 最终目的国（地区） | P19: 境内货源地 | S19: 征免 | T19: 净重 | U19: 毛重 | V19: 件数
A20: 1 | B20: =VLOOKUP(A20,申报要素!A:F,3,0) -> 9113900090 | D20: =VLOOKUP(A20,申报要素!A:F,2,0) -> 编织表带 | I20: 12 | K20: 中国 | M20: =$G$10 -> 英国 | P20: 深圳特区 | S20: 照章征税 | T20: 6 | U20: 6 | V20: 2
D21: =VLOOKUP(A20,申报要素!A:F,6,0) -> BG-20-01 | I21: =G22*I20 -> 2880
G22: 240 | H22: 条 | I22: 人民币
A23: 2 | B23: =VLOOKUP(A23,申报要素!A:F,3,0) -> 9113900090 | D23: =VLOOKUP(A23,申报要素!A:F,2,0) -> 编织表带 | I23: 18 | K23: 中国 | M23: =$G$10 -> 英国 | P23: 深圳特区 | S23: 照章征税 | T23: 1.5 | U23: 1.5
D24: =VLOOKUP(A23,申报要素!A:F,6,0) -> BSX1-22-01 | I24: =G25*I23 -> 1080
G25: 60 | H25: 条 | I25: 人民币
A26: 3 | B26: =VLOOKUP(A26,申报要素!A:F,3,0) -> 9113900090 | D26: =VLOOKUP(A26,申报要素!A:F,2,0) -> 编织表带 | I26: 14 | K26: 中国 | M26: =$G$10 -> 英国 | P26: 深圳特区 | S26: 照章征税 | T26: 4 | U26: 4
D27: =VLOOKUP(A26,申报要素!A:F,6,0) -> PG1-45-01 | I27: =G28*I26 -> 2170
G28: 155 | H28: 条 | I28: 人民币
A29: 4 | B29: =VLOOKUP(A29,申报要素!A:F,3,0) -> 9113900090 | D29: =VLOOKUP(A29,申报要素!A:F,2,0) -> 编织表带 | I29: 15 | K29: 中国 | M29: =$G$10 -> 英国 | P29: 深圳特区 | S29: 照章征税 | T29: 7 | U29: 7.8
D30: =VLOOKUP(A29,申报要素!A:F,6,0) -> QB-16 | I30: =G31*I29 -> 4650
G31: 310 | H31: 条 | I31: 人民币
A32: 5 | B32: =VLOOKUP(A32,申报要素!A:F,3,0) -> 9113900090 | D32: =VLOOKUP(A32,申报要素!A:F,2,0) -> 编织表带 | I32: 18 | K32: 中国 | M32: =$G$10 -> 英国 | P32: 深圳特区 | S32: 照章征税 | T32: 4 | U32: 5
D33: =VLOOKUP(A32,申报要素!A:F,6,0) -> SX1-22-01 | I33: =G34*I32 -> 3420
G34: 190 | H34: 条 | I34: 人民币
A35: 6 | B35: =VLOOKUP(A35,申报要素!A:F,3,0) -> 9113900090 | D35: =VLOOKUP(A35,申报要素!A:F,2,0) -> 编织表带 | I35: 17 | K35: 中国 | M35: =$G$10 -> 英国 | P35: 深圳特区 | S35: 照章征税 | T35: 2 | U35: 2.5
D36: =VLOOKUP(A35,申报要素!A:F,6,0) -> SX2-22-01 | I36: =G37*I35 -> 1785
G37: 105 | H37: 条 | I37: 人民币
A38: 7 | B38: =VLOOKUP(A38,申报要素!A:F,3,0) -> 9113900090 | D38: =VLOOKUP(A38,申报要素!A:F,2,0) -> 编织表带 | I38: 18 | K38: 中国 | M38: =$G$10 -> 英国 | P38: 深圳特区 | S38: 照章征税 | T38: 3 | U38: 3.5
D39: =VLOOKUP(A38,申报要素!A:F,6,0) -> SX3-22-01 | I39: =G40*I38 -> 2520
G40: 140 | H40: 条 | I40: 人民币
...

Sheet 申报要素
A1: (产品或者包装上有明显的logo，带R，TM标识的商标必须申报为品牌，有显示型号（model，type no.）的必须申报为型号)(申报的牌子型号要在产品或包装上有一模一样显示，海关查货的话会去比对拍照，对不上会升级整车查验和压车改单）
A2: (申报的牌子型号要在产品或包装上有一模一样显示，海关查货的话会去比对拍照，对不上会升级整车查验和压车改单）
A3: 检验检疫附加编号：通过以下网站输入10位HS编号，再根据申报要素细分确定3位检疫附加编号
C4: https://e-service.shciq.gov.cn/shesp/
A5: 申报要素查询网址： | C5: http://www.hscode.net/IntegrateQueries/QueryYS/
A8: 申报要素
A9: 序号 | B9: 品名 | C9: 海关HS编码 | D9: 检疫附加码 | E9: 品牌 | F9: 型号 | G9: 品牌类型 | H9: 出口享惠情况 | I9: 其他申报要素
A10: 1 | B10: 编织表带 | C10: 9113900090 | E10: 0无品牌 | F10: BG-20-01 | G10: 0无品牌 | H10: 0不享惠 | I10: 尼龙
A11: 2 | B11: 编织表带 | C11: 9113900090 | E11: 0无品牌 | F11: BSX1-22-01 | G11: 0无品牌 | H11: 0不享惠 | I11: 尼龙
A12: 3 | B12: 编织表带 | C12: 9113900090 | E12: 0无品牌 | F12: PG1-45-01 | G12: 0无品牌 | H12: 0不享惠 | I12: 尼龙
A13: 4 | B13: 编织表带 | C13: 9113900090 | E13: 0无品牌 | F13: QB-16 | G13: 0无品牌 | H13: 0不享惠 | I13: 尼龙
A14: 5 | B14: 编织表带 | C14: 9113900090 | E14: 0无品牌 | F14: SX1-22-01 | G14: 0无品牌 | H14: 0不享惠 | I14: 尼龙
A15: 6 | B15: 编织表带 | C15: 9113900090 | E15: 0无品牌 | F15: SX2-22-01 | G15: 0无品牌 | H15: 0不享惠 | I15: 尼龙
A16: 7 | B16: 编织表带 | C16: 9113900090 | E16: 0无品牌 | F16: SX3-22-01 | G16: 0无品牌 | H16: 0不享惠 | I16: 尼龙
A17: 8 | B17: 表带 | C17: 9113900090 | E17: 0无品牌 | F17: XY140-L1 | G17: 0无品牌 | H17: 0不享惠 | I17: 硅胶
A18: 9 | B18: 表带 | C18: 9113900090 | E18: 0无品牌 | F18: XY140-S1 | G18: 0无品牌 | H18: 0不享惠 | I18: 硅胶
A19: 10 | B19: 表带 | C19: 9113200000 | E19: 0无品牌 | F19: XY37-1 | G19: 0无品牌 | H19: 0不享惠 | I19: 金属
A20: 11 | B20: 表带 | C20: 9113200000 | E20: 0无品牌 | F20: XY37-3 | G20: 0无品牌 | H20: 0不享惠 | I20: 金属
A21: 12 | B21: 硅胶表带 | C21: 9113900090 | E21: 0无品牌 | F21: ZF-3 | G21: 0无品牌 | H21: 0不享惠 | I21: 硅胶
... A59: 50 | B59: 手表表带 | C59: 9113200000 | E59: 0无品牌 | F59: ZY2-3 | G59: 0无品牌 | H59: 0不享惠 | I59: 金属

Sheet 填制规范
A1: 项目 | B1: 2018年8月实行新的报关单的填制规范，红色为新增的项目
A3: 境内收发货人 | B3: 填报在海关备案的对外签订并执行进出口贸易合同的中国境内法人、其他组织名称及编码。编码填报18位法人和其他组织统一社会信用代码，没有统一社会信用代码的，填报其在海关的备案编码。
A5: 进出境关别 | B5: 根据货物实际进出境的口岸海关，填报海关规定的《关区代码表》中相应口岸海关的名称及代码。
A7: 备案号 | B7: 填报进出口货物收发货人、消费使用单位、生产销售单位在海关办理加工贸易合同备案或征、减、免税审核确认等手续时，海关核发的《加工贸易手册》、海关特殊监管区域和保税监管场所保税账册、《征免税证明》或其他备案审批文件的编号。一份报关单只允许填报一个备案号。
A9: 境外收发货人 | B9: 非互认国家（地区）AEO企业等其他情形，编码免于填报。境外收货人通常指签订并执行出口贸易合同中的买方或合同指定的收货人，境外发货人通常指签订并执行进口贸易合同中的卖方。填报境外收发货人的名称及编码。名称一般填报英文名称，检验检疫要求填报其他外文名称的，在英文名称后填报，以半角括号分隔；对于AEO互认国家（地区）企业的，编码填报AEO编码，填报样式按照海关总署发布的相关公告要求填报（如新加坡AEO企业填报样式为：SG123456789012，韩国AEO企业填报样式为KR1234567，具体见相关公告要求）。
A11: 货物存放地点-进口 | B11: 填报货物进境后存放的场所或地点，包括海关监管作业场所、分拨仓库、定点加工厂、隔离检疫场、企业自有仓库等。
A13: 消费使用单位-进口 | B13: 消费使用单位填报已知的进口货物在境内的最终消费、使用单位的名称，包括：1．自行进口货物的单位。2．委托进出口企业进口货物的单位。
A15: 生产销售单位-出口 | B15: 生产销售单位填报出口货物在境内的生产或销售单位的名称，包括：1．自行出口货物的单位。2．委托进出口企业出口货物的单位。
A17: 许可证号 | B17: 填报进（出）口许可证、两用物项和技术进（出）口许可证、两用物项和技术出口许可证（定向）、纺织品临时出口许可证、出口许可证（加工贸易）、出口许可证（边境小额贸易）的编号。一份报关单只允许填报一个许可证号。
A19: 启运港-进口 | B19: 填报进口货物在运抵我国关境前的第一个境外装运港。
A21: 合同协议号 | B21: 填报进出口货物合同（包括协议或订单）编号。未发生商业性交易的免予填报。
A23: 贸易国(地区) | B23: 发生商业性交易的进口填报购自国（地区），出口填报售予国（地区）。未发生商业性交易的填报货物所有权拥有者所属的国家（地区）。
... A91: 自报自缴 | B91: 进出口企业、单位采用“自主申报、自行缴税”（自报自缴）模式向海关申报时，填报“是”；反之则填报“否”。

Sheet 发票
A1: 發票 INVOICE
G2: 編 號 NO: | H2: =报关单!A10 -> 2026011202
A3: 商 號 Sold to Massrs: | C3: =报关单!A6 -> HONG KONG YUN QI LIAN TECHNOLOGY LIMITED | G3: 日 期 DATE: | H3: =TODAY() -> 46155
G6: 成交方式： | H6: =报关单!V4 -> FOB | I6: =报关单!W4 -> SHENZHEN
A7: 標記號碼 Mark & No | C7: 貨物名稱 Description | D7: 型号 Model | E7: 數量 Quantity | G7: 單價 Unit price | H7: 總金額 Amount
C8: =OFFSET(报关单!$D$1,ROW(报关单!D1)*3+16,0) -> 编织表带 | D8: =OFFSET(报关单!$D$1,ROW(报关单!E1)*3+17,0) -> BG-20-01 | E8: =OFFSET(报关单!$G$1,ROW(报关单!G1)*3+18,0) -> 240 | F8: =OFFSET(报关单!$H$1,ROW(报关单!H1)*3+18,0) -> 条 | G8: =IFERROR(I8/E8,0) -> 12 | H8: =OFFSET(报关单!$I$1,ROW(报关单!I1)*3+18,0) -> 人民币 | I8: =OFFSET(报关单!$I$1,ROW(报关单!I1)*3+17,0) -> 2880
C9: =OFFSET(报关单!$D$1,ROW(报关单!D2)*3+16,0) -> 编织表带 | D9: =OFFSET(报关单!$D$1,ROW(报关单!E2)*3+17,0) -> BSX1-22-01 | E9: =OFFSET(报关单!$G$1,ROW(报关单!G2)*3+18,0) -> 60 | F9: =OFFSET(报关单!$H$1,ROW(报关单!H2)*3+18,0) -> 条 | G9: =IFERROR(I9/E9,0) -> 18 | H9: =OFFSET(报关单!$I$1,ROW(报关单!I2)*3+18,0) -> 人民币 | I9: =OFFSET(报关单!$I$1,ROW(报关单!I2)*3+17,0) -> 1080
C10: =OFFSET(报关单!$D$1,ROW(报关单!D3)*3+16,0) -> 编织表带 | D10: =OFFSET(报关单!$D$1,ROW(报关单!E3)*3+17,0) -> PG1-45-01 | E10: =OFFSET(报关单!$G$1,ROW(报关单!G3)*3+18,0) -> 155 | F10: =OFFSET(报关单!$H$1,ROW(报关单!H3)*3+18,0) -> 条 | G10: =IFERROR(I10/E10,0) -> 14 | H10: =OFFSET(报关单!$I$1,ROW(报关单!I3)*3+18,0) -> 人民币 | I10: =OFFSET(报关单!$I$1,ROW(报关单!I3)*3+17,0) -> 2170
C11: =OFFSET(报关单!$D$1,ROW(报关单!D4)*3+16,0) -> 编织表带 | D11: =OFFSET(报关单!$D$1,ROW(报关单!E4)*3+17,0) -> QB-16 | E11: =OFFSET(报关单!$G$1,ROW(报关单!G4)*3+18,0) -> 310 | F11: =OFFSET(报关单!$H$1,ROW(报关单!H4)*3+18,0) -> 条 | G11: =IFERROR(I11/E11,0) -> 15 | H11: =OFFSET(报关单!$I$1,ROW(报关单!I4)*3+18,0) -> 人民币 | I11: =OFFSET(报关单!$I$1,ROW(报关单!I4)*3+17,0) -> 4650
C12: =OFFSET(报关单!$D$1,ROW(报关单!D5)*3+16,0) -> 编织表带 | D12: =OFFSET(报关单!$D$1,ROW(报关单!E5)*3+17,0) -> SX1-22-01 | E12: =OFFSET(报关单!$G$1,ROW(报关单!G5)*3+18,0) -> 190 | F12: =OFFSET(报关单!$H$1,ROW(报关单!H5)*3+18,0) -> 条 | G12: =IFERROR(I12/E12,0) -> 18 | H12: =OFFSET(报关单!$I$1,ROW(报关单!I5)*3+18,0) -> 人民币 | I12: =OFFSET(报关单!$I$1,ROW(报关单!I5)*3+17,0) -> 3420
C13: =OFFSET(报关单!$D$1,ROW(报关单!D6)*3+16,0) -> 编织表带 | D13: =OFFSET(报关单!$D$1,ROW(报关单!E6)*3+17,0) -> SX2-22-01 | E13: =OFFSET(报关单!$G$1,ROW(报关单!G6)*3+18,0) -> 105 | F13: =OFFSET(报关单!$H$1,ROW(报关单!H6)*3+18,0) -> 条 | G13: =IFERROR(I13/E13,0) -> 17 | H13: =OFFSET(报关单!$I$1,ROW(报关单!I6)*3+18,0) -> 人民币 | I13: =OFFSET(报关单!$I$1,ROW(报关单!I6)*3+17,0) -> 1785
C14: =OFFSET(报关单!$D$1,ROW(报关单!D7)*3+16,0) -> 编织表带 | D14: =OFFSET(报关单!$D$1,ROW(报关单!E7)*3+17,0) -> SX3-22-01 | E14: =OFFSET(报关单!$G$1,ROW(报关单!G7)*3+18,0) -> 140 | F14: =OFFSET(报关单!$H$1,ROW(报关单!H7)*3+18,0) -> 条 | G14: =IFERROR(I14/E14,0) -> 18 | H14: =OFFSET(报关单!$I$1,ROW(报关单!I7)*3+18,0) -> 人民币 | I14: =OFFSET(报关单!$I$1,ROW(报关单!I7)*3+17,0) -> 2520
C15: =OFFSET(报关单!$D$1,ROW(报关单!D8)*3+16,0) -> 表带 | D15: =OFFSET(报关单!$D$1,ROW(报关单!E8)*3+17,0) -> XY140-L1 | E15: =OFFSET(报关单!$G$1,ROW(报关单!G8)*3+18,0) -> 20 | F15: =OFFSET(报关单!$H$1,ROW(报关单!H8)*3+18,0) -> 条 | G15: =IFERROR(I15/E15,0) -> 6.5 | H15: =OFFSET(报关单!$I$1,ROW(报关单!I8)*3+18,0) -> 人民币 | I15: =OFFSET(报关单!$I$1,ROW(报关单!I8)*3+17,0) -> 130
C16: =OFFSET(报关单!$D$1,ROW(报关单!D9)*3+16,0) -> 表带 | D16: =OFFSET(报关单!$D$1,ROW(报关单!E9)*3+17,0) -> XY140-S1 | E16: =OFFSET(报关单!$G$1,ROW(报关单!G9)*3+18,0) -> 60 | F16: =OFFSET(报关单!$H$1,ROW(报关单!H9)*3+18,0) -> 条 | G16: =IFERROR(I16/E16,0) -> 6.5 | H16: =OFFSET(报关单!$I$1,ROW(报关单!I9)*3+18,0) -> 人民币 | I16: =OFFSET(报关单!$I$1,ROW(报关单!I9)*3+17,0) -> 390
C17: =OFFSET(报关单!$D$1,ROW(报关单!D10)*3+16,0) -> 表带 | D17: =OFFSET(报关单!$D$1,ROW(报关单!E10)*3+17,0) -> XY37-1 | E17: =OFFSET(报关单!$G$1,ROW(报关单!G10)*3+18,0) -> 15 | F17: =OFFSET(报关单!$H$1,ROW(报关单!H10)*3+18,0) -> 条 | G17: =IFERROR(I17/E17,0) -> 8 | H17: =OFFSET(报关单!$I$1,ROW(报关单!I10)*3+18,0) -> 人民币 | I17: =OFFSET(报关单!$I$1,ROW(报关单!I10)*3+17,0) -> 120
C18: =OFFSET(报关单!$D$1,ROW(报关单!D11)*3+16,0) -> 表带 | D18: =OFFSET(报关单!$D$1,ROW(报关单!E11)*3+17,0) -> XY37-3 | E18: =OFFSET(报关单!$G$1,ROW(报关单!G11)*3+18,0) -> 15 | F18: =OFFSET(报关单!$H$1,ROW(报关单!H11)*3+18,0) -> 条 | G18: =IFERROR(I18/E18,0) -> 8 | H18: =OFFSET(报关单!$I$1,ROW(报关单!I11)*3+18,0) -> 人民币 | I18: =OFFSET(报关单!$I$1,ROW(报关单!I11)*3+17,0) -> 120
C19: =OFFSET(报关单!$D$1,ROW(报关单!D12)*3+16,0) -> 硅胶表带 | D19: =OFFSET(报关单!$D$1,ROW(报关单!E12)*3+17,0) -> ZF-3 | E19: =OFFSET(报关单!$G$1,ROW(报关单!G12)*3+18,0) -> 100 | F19: =OFFSET(报关单!$H$1,ROW(报关单!H12)*3+18,0) -> 条 | G19: =IFERROR(I19/E19,0) -> 6 | H19: =OFFSET(报关单!$I$1,ROW(报关单!I12)*3+18,0) -> 人民币 | I19: =OFFSET(报关单!$I$1,ROW(报关单!I12)*3+17,0) -> 600
... C51: =OFFSET(报关单!$D$1,ROW(报关单!D44)*3+16,0) -> 手表表带 | D51: =OFFSET(报关单!$D$1,ROW(报关单!E44)*3+17,0) -> ZY2-3 | E51: =OFFSET(报关单!$G$1,ROW(报关单!G44)*3+18,0) -> 5 | F51: =OFFSET(报关单!$H$1,ROW(报关单!H44)*3+18,0) -> 条 | G51: =IFERROR(I51/E51,0) -> 32 | H51: =OFFSET(报关单!$I$1,ROW(报关单!I44)*3+18,0) -> 人民币 | I51: =OFFSET(报关单!$I$1,ROW(报关单!I44)*3+17,0) -> 160
A55: =IF(H55="CNY","总计人民币:",IF(H55="USD","总计美元: "," ")) | C55: 人民币贰万零贰拾伍圆整 | G55: TOTAL: | H55: =H8 -> 人民币 | I55: =SUM(I8:I54) -> 24985
A56: 唛头 Marks | G56: 备注：
C62: .

Sheet 箱单
B2: 装 箱 单 PACKING LIST
G3: 日期 Date： | H3: =TODAY() -> 46155
G4: 发票编号 Invoice No: | H4: =发票!H2 -> 2026011202
A5: 客户 To Messrs: | B5: =发票!C3 -> HONG KONG YUN QI LIAN TECHNOLOGY LIMITED | G5: 合同号 Contract No: | H5: =发票!H2 -> 2026011202
A7: 船名 Shipped by： | D7: 由 深圳 至 | E7: =报关单!M20 -> 英国 | G7: 付款条件 Terms of Payment: | H7: =报关单!Y4 -> 电汇 先出后结
A9: 箱号 Ctn.No. | B9: 货物名称及规格 Description | C9: 型号 Model | D9: 箱数： Pkg： | E9: 数量： Ge.Quantity | G9: 毛重(KG)： G.W.(KG): | H9: 净重(KG)： N.W.(KG):
A10: =发票!A8 -> 0 | B10: =发票!C8 -> 编织表带 | C10: =发票!D8 -> BG-20-01 | D10: 2 | E10: =发票!E8 -> 240 | F10: =发票!F8 -> 条 | G10: =OFFSET(报关单!$U$1,ROW(报关单!U1)*3+16,0) -> 6 | H10: =OFFSET(报关单!$T$1,ROW(报关单!T1)*3+16,0) -> 6
B11: =发票!C9 -> 编织表带 | C11: =发票!D9 -> BSX1-22-01 | E11: =发票!E9 -> 60 | F11: =发票!F9 -> 条 | G11: =OFFSET(报关单!$U$1,ROW(报关单!U2)*3+16,0) -> 1.5 | H11: =OFFSET(报关单!$T$1,ROW(报关单!T2)*3+16,0) -> 1.5
B12: =发票!C10 -> 编织表带 | C12: =发票!D10 -> PG1-45-01 | E12: =发票!E10 -> 155 | F12: =发票!F10 -> 条 | G12: =OFFSET(报关单!$U$1,ROW(报关单!U3)*3+16,0) -> 4 | H12: =OFFSET(报关单!$T$1,ROW(报关单!T3)*3+16,0) -> 4
B13: =发票!C11 -> 编织表带 | C13: =发票!D11 -> QB-16 | D13: =OFFSET(报关单!$V$1,ROW(报关单!V4)*3+16,0) -> 0 | E13: =发票!E11 -> 310 | F13: =发票!F11 -> 条 | G13: =OFFSET(报关单!$U$1,ROW(报关单!U4)*3+16,0) -> 7.8 | H13: =OFFSET(报关单!$T$1,ROW(报关单!T4)*3+16,0) -> 7
B14: =发票!C12 -> 编织表带 | C14: =发票!D12 -> SX1-22-01 | D14: =OFFSET(报关单!$V$1,ROW(报关单!V5)*3+16,0) -> 0 | E14: =发票!E12 -> 190 | F14: =发票!F12 -> 条 | G14: =OFFSET(报关单!$U$1,ROW(报关单!U5)*3+16,0) -> 5 | H14: =OFFSET(报关单!$T$1,ROW(报关单!T5)*3+16,0) -> 4
B15: =发票!C13 -> 编织表带 | C15: =发票!D13 -> SX2-22-01 | D15: =OFFSET(报关单!$V$1,ROW(报关单!V6)*3+16,0) -> 0 | E15: =发票!E13 -> 105 | F15: =发票!F13 -> 条 | G15: =OFFSET(报关单!$U$1,ROW(报关单!U6)*3+16,0) -> 2.5 | H15: =OFFSET(报关单!$T$1,ROW(报关单!T6)*3+16,0) -> 2
B16: =发票!C14 -> 编织表带 | C16: =发票!D14 -> SX3-22-01 | D16: =OFFSET(报关单!$V$1,ROW(报关单!V7)*3+16,0) -> 0 | E16: =发票!E14 -> 140 | F16: =发票!F14 -> 条 | G16: =OFFSET(报关单!$U$1,ROW(报关单!U7)*3+16,0) -> 3.5 | H16: =OFFSET(报关单!$T$1,ROW(报关单!T7)*3+16,0) -> 3
B17: =发票!C15 -> 表带 | C17: =发票!D15 -> XY140-L1 | D17: =OFFSET(报关单!$V$1,ROW(报关单!V8)*3+16,0) -> 0 | E17: =发票!E15 -> 20 | F17: =发票!F15 -> 条 | G17: =OFFSET(报关单!$U$1,ROW(报关单!U8)*3+16,0) -> 0.4 | H17: =OFFSET(报关单!$T$1,ROW(报关单!T8)*3+16,0) -> 0.4
B18: =发票!C16 -> 表带 | C18: =发票!D16 -> XY140-S1 | D18: =OFFSET(报关单!$V$1,ROW(报关单!V9)*3+16,0) -> 0 | E18: =发票!E16 -> 60 | F18: =发票!F16 -> 条 | G18: =OFFSET(报关单!$U$1,ROW(报关单!U9)*3+16,0) -> 1.5 | H18: =OFFSET(报关单!$T$1,ROW(报关单!T9)*3+16,0) -> 1.5
B19: =发票!C17 -> 表带 | C19: =发票!D17 -> XY37-1 | D19: =OFFSET(报关单!$V$1,ROW(报关单!V10)*3+16,0) -> 0 | E19: =发票!E17 -> 15 | F19: =发票!F17 -> 条 | G19: =OFFSET(报关单!$U$1,ROW(报关单!U10)*3+16,0) -> 0.4 | H19: =OFFSET(报关单!$T$1,ROW(报关单!T10)*3+16,0) -> 0.4
B20: =发票!C18 -> 表带 | C20: =发票!D18 -> XY37-3 | D20: =OFFSET(报关单!$V$1,ROW(报关单!V11)*3+16,0) -> 0 | E20: =发票!E18 -> 15 | F20: =发票!F18 -> 条 | G20: =OFFSET(报关单!$U$1,ROW(报关单!U11)*3+16,0) -> 0.4 | H20: =OFFSET(报关单!$T$1,ROW(报关单!T11)*3+16,0) -> 0.4
B21: =发票!C19 -> 硅胶表带 | C21: =发票!D19 -> ZF-3 | D21: =OFFSET(报关单!$V$1,ROW(报关单!V12)*3+16,0) -> 0 | E21: =发票!E19 -> 100 | F21: =发票!F19 -> 条 | G21: =OFFSET(报关单!$U$1,ROW(报关单!U12)*3+16,0) -> 2.5 | H21: =OFFSET(报关单!$T$1,ROW(报关单!T12)*3+16,0) -> 2
B22: =发票!C20 -> 手表表带 | C22: =发票!D20 -> ZY2-3 | D22: =OFFSET(报关单!$V$1,ROW(报关单!V13)*3+16,0) -> 0 | E22: =发票!E20 -> 5 | F22: =发票!F20 -> 条 | G22: =OFFSET(报关单!$U$1,ROW(报关单!T13)*3+16,0) -> 0.1 | H22: =OFFSET(报关单!$T$1,ROW(报关单!T13)*3+16,0) -> 0.1
B23: =发票!C21 -> 手表表带 | C23: =发票!D21 -> ZY2-3 | D23: =OFFSET(报关单!$V$1,ROW(报关单!V14)*3+16,0) -> 0 | E23: =发票!E21 -> 5 | F23: =发票!F21 -> 条 | G23: =OFFSET(报关单!$U$1,ROW(报关单!T14)*3+16,0) -> 0.1 | H23: =OFFSET(报关单!$T$1,ROW(报关单!T14)*3+16,0) -> 0.1
B24: =发票!C22 -> 手表表带 | C24: =发票!D22 -> ZY2-3 | D24: =OFFSET(报关单!$V$1,ROW(报关单!V15)*3+16,0) -> 0 | E24: =发票!E22 -> 5 | F24: =发票!F22 -> 条 | G24: =OFFSET(报关单!$U$1,ROW(报关单!T15)*3+16,0) -> 0.1 | H24: =OFFSET(报关单!$T$1,ROW(报关单!T15)*3+16,0) -> 0.1
B25: =发票!C23 -> 手表表带 | C25: =发票!D23 -> ZY2-3 | D25: =OFFSET(报关单!$V$1,ROW(报关单!V16)*3+16,0) -> 0 | E25: =发票!E23 -> 5 | F25: =发票!F23 -> 条 | G25: =OFFSET(报关单!$U$1,ROW(报关单!T16)*3+16,0) -> 0.1 | H25: =OFFSET(报关单!$T$1,ROW(报关单!T16)*3+16,0) -> 0.1
B26: =发票!C24 -> 手表表带 | C26: =发票!D24 -> ZY2-3 | D26: =OFFSET(报关单!$V$1,ROW(报关单!V17)*3+16,0) -> 0 | E26: =发票!E24 -> 5 | F26: =发票!F24 -> 条 | G26: =OFFSET(报关单!$U$1,ROW(报关单!T17)*3+16,0) -> 0.1 | H26: =OFFSET(报关单!$T$1,ROW(报关单!T17)*3+16,0) -> 0.1
B27: =发票!C25 -> 手表表带 | C27: =发票!D25 -> ZY2-3 | D27: =OFFSET(报关单!$V$1,ROW(报关单!V18)*3+16,0) -> 0 | E27: =发票!E25 -> 5 | F27: =发票!F25 -> 条 | G27: =OFFSET(报关单!$U$1,ROW(报关单!T18)*3+16,0) -> 0.1 | H27: =OFFSET(报关单!$T$1,ROW(报关单!T18)*3+16,0) -> 0.1
B28: =发票!C26 -> 手表表带 | C28: =发票!D26 -> ZY2-3 | D28: =OFFSET(报关单!$V$1,ROW(报关单!V19)*3+16,0) -> 0 | E28: =发票!E26 -> 5 | F28: =发票!F26 -> 条 | G28: =OFFSET(报关单!$U$1,ROW(报关单!T19)*3+16,0) -> 0.1 | H28: =OFFSET(报关单!$T$1,ROW(报关单!T19)*3+16,0) -> 0.1
B29: =发票!C27 -> 手表表带 | C29: =发票!D27 -> ZY2-3 | D29: =OFFSET(报关单!$V$1,ROW(报关单!V20)*3+16,0) -> 0 | E29: =发票!E27 -> 5 | F29: =发票!F27 -> 条 | G29: =OFFSET(报关单!$U$1,ROW(报关单!T20)*3+16,0) -> 0.1 | H29: =OFFSET(报关单!$T$1,ROW(报关单!T20)*3+16,0) -> 0.1
B30: =发票!C28 -> 手表表带 | C30: =发票!D28 -> ZY2-3 | D30: =OFFSET(报关单!$V$1,ROW(报关单!V21)*3+16,0) -> 0 | E30: =发票!E28 -> 5 | F30: =发票!F28 -> 条 | G30: =OFFSET(报关单!$U$1,ROW(报关单!T21)*3+16,0) -> 0.1 | H30: =OFFSET(报关单!$T$1,ROW(报关单!T21)*3+16,0) -> 0.1
B31: =发票!C29 -> 手表表带 | C31: =发票!D29 -> ZY2-3 | D31: =OFFSET(报关单!$V$1,ROW(报关单!V22)*3+16,0) -> 0 | E31: =发票!E29 -> 5 | F31: =发票!F29 -> 条 | G31: =OFFSET(报关单!$U$1,ROW(报关单!T22)*3+16,0) -> 0.1 | H31: =OFFSET(报关单!$T$1,ROW(报关单!T22)*3+16,0) -> 0.1
B32: =发票!C30 -> 手表表带 | C32: =发票!D30 -> ZY2-3 | D32: =OFFSET(报关单!$V$1,ROW(报关单!V23)*3+16,0) -> 0 | E32: =发票!E30 -> 5 | F32: =发票!F30 -> 条 | G32: =OFFSET(报关单!$U$1,ROW(报关单!T23)*3+16,0) -> 0.1 | H32: =OFFSET(报关单!$T$1,ROW(报关单!T23)*3+16,0) -> 0.1
B33: =发票!C31 -> 手表表带 | C33: =发票!D31 -> ZY2-3 | D33: =OFFSET(报关单!$V$1,ROW(报关单!V24)*3+16,0) -> 0 | E33: =发票!E31 -> 5 | F33: =发票!F31 -> 条 | G33: =OFFSET(报关单!$U$1,ROW(报关单!T24)*3+16,0) -> 0.1 | H33: =OFFSET(报关单!$T$1,ROW(报关单!T24)*3+16,0) -> 0.1
... B40: =发票!C38 -> 手表表带 | C40: =发票!D38 -> ZY2-3 | D40: =OFFSET(报关单!$V$1,ROW(报关单!V31)*3+16,0) -> 0 | E40: =发票!E38 -> 5 | F40: =发票!F38 -> 条 | G40: =OFFSET(报关单!$U$1,ROW(报关单!T31)*3+16,0) -> 0.1 | H40: =OFFSET(报关单!$T$1,ROW(报关单!T31)*3+16,0) -> 0.1
A41: 合计 Total | D41: =SUM(D10:D25) -> 2 | G41: =SUM(G10:G40) -> 37.4 | H41: =SUM(H10:H40) -> 34.1
A42: 唛头 Marks

Sheet 合同
B1: 合 同 SALES CONTRACT
B2: 卖 方： | C2: =报关单!V5 -> 深圳市新棱镜贸易有限公司
B3: Sellers:
B4: 地 址： | C4: =报关单!V6 -> 1702, Block C, Rongchuang Zhihui Building, Longhua District, Shenzhen City, China.
B5: Address: | G5: 合同号码
B6: 电 话： | C6: =报关单!V7 -> 18823202180 | E6: 传 真 | F6: =报关单!Y7 -> 0 | G6: Contract No: | H6: =报关单!A10 -> 2026011202
B7: TEL: | E7: FAX: | G7: 日 期
B8: 买 方： | C8: =报关单!V8 -> HONG KONG YUN QI LIAN TECHNOLOGY LIMITED | G8: Date: | H8: 2026.01.10
B9: Buyers： | G9: 签约地点
B10: 地 址： | C10: =报关单!V9 -> RM 10, 23/F NEW TREND CTR NO704 PRINCE EDWARD RD EAST SANPO KONGHONG KONG | G10: Signed at: | H10: =报关单!V3 -> 深圳
B11: Address: | G11: 成交方式： Trade Term: | H11: =报关单!V4 -> FOB | I11: =报关单!W4 -> SHENZHEN
B12: 电 话 | C12: =报关单!V10 -> 13071079299 | E12: 传 真 | F12: =报关单!Y10 -> 0
B13: TEL: | E13: FAX:
B14: 经买卖双方确认根据下列条款订立本合同
B15: This contract is made out by the Sellers and Buyers as per the following terms and conditions mutuilly confirmed:
B16: (1)货物名称 | D16: (2) 型号 model | E16: (3) 数 量 | F16: (4)单 位 | G16: (5)单价 | H16: (6) 金 额
B17: Name of commodity | D17: Model | E17: Quantity | F17: Unit | G17: Unit Price | H17: Amount
B18: =发票!C8 -> 编织表带 | D18: =发票!D8 -> BG-20-01 | E18: =发票!E8 -> 240 | F18: =发票!F8 -> 条 | G18: =发票!G8 -> 12 | H18: =发票!H8 -> 人民币 | I18: =发票!I8 -> 2880
B19: =发票!C9 -> 编织表带 | D19: =发票!D9 -> BSX1-22-01 | E19: =发票!E9 -> 60 | F19: =发票!F9 -> 条 | G19: =发票!G9 -> 18 | H19: =发票!H9 -> 人民币 | I19: =发票!I9 -> 1080
B20: =发票!C10 -> 编织表带 | D20: =发票!D10 -> PG1-45-01 | E20: =发票!E10 -> 155 | F20: =发票!F10 -> 条 | G20: =发票!G10 -> 14 | H20: =发票!H10 -> 人民币 | I20: =发票!I10 -> 2170
B21: =发票!C11 -> 编织表带 | D21: =发票!D11 -> QB-16 | E21: =发票!E11 -> 310 | F21: =发票!F11 -> 条 | G21: =发票!G11 -> 15 | H21: =发票!H11 -> 人民币 | I21: =发票!I11 -> 4650
B22: =发票!C12 -> 编织表带 | D22: =发票!D12 -> SX1-22-01 | E22: =发票!E12 -> 190 | F22: =发票!F12 -> 条 | G22: =发票!G12 -> 18 | H22: =发票!H12 -> 人民币 | I22: =发票!I12 -> 3420
B23: =发票!C13 -> 编织表带 | D23: =发票!D13 -> SX2-22-01 | E23: =发票!E13 -> 105 | F23: =发票!F13 -> 条 | G23: =发票!G13 -> 17 | H23: =发票!H13 -> 人民币 | I23: =发票!I13 -> 1785
B24: =发票!C14 -> 编织表带 | D24: =发票!D14 -> SX3-22-01 | E24: =发票!E14 -> 140 | F24: =发票!F14 -> 条 | G24: =发票!G14 -> 18 | H24: =发票!H14 -> 人民币 | I24: =发票!I14 -> 2520
B25: =发票!C15 -> 表带 | D25: =发票!D15 -> XY140-L1 | E25: =发票!E15 -> 20 | F25: =发票!F15 -> 条 | G25: =发票!G15 -> 6.5 | H25: =发票!H15 -> 人民币 | I25: =发票!I15 -> 130
B26: =发票!C16 -> 表带 | D26: =发票!D16 -> XY140-S1 | E26: =发票!E16 -> 60 | F26: =发票!F16 -> 条 | G26: =发票!G16 -> 6.5 | H26: =发票!H16 -> 人民币 | I26: =发票!I16 -> 390
B27: =发票!C17 -> 表带 | D27: =发票!D17 -> XY37-1 | E27: =发票!E17 -> 15 | F27: =发票!F17 -> 条 | G27: =发票!G17 -> 8 | H27: =发票!H17 -> 人民币 | I27: =发票!I17 -> 120
B28: =发票!C18 -> 表带 | D28: =发票!D18 -> XY37-3 | E28: =发票!E18 -> 15 | F28: =发票!F18 -> 条 | G28: =发票!G18 -> 8 | H28: =发票!H18 -> 人民币 | I28: =发票!I18 -> 120
B29: =发票!C19 -> 硅胶表带 | D29: =发票!D19 -> ZF-3 | E29: =发票!E19 -> 100 | F29: =发票!F19 -> 条 | G29: =发票!G19 -> 6 | H29: =发票!H19 -> 人民币 | I29: =发票!I19 -> 600
... B47: =发票!C37 -> 手表表带 | D47: =发票!D37 -> ZY2-3 | E47: =发票!E37 -> 5 | F47: =发票!F37 -> 条 | G47: =发票!G37 -> 32 | H47: =发票!H37 -> 人民币 | I47: =发票!I37 -> 160
B51: 数量及总值允许有 2 %的增减。 | G51: 总 值 | H51: =H18 -> 人民币 | I51: =SUM(I18:K50) -> 22745
B52: 2 % more or less both in amount and quantity allowed. | G52: Total Amount:
B53: (6)合同总值（大写） | E53: =IF(H51="CNY","总计人民币:",IF(H51="USD","总计美元: "," ")) | F53: 人民币贰万零贰拾伍圆整
B55: (7)包装及唛头
B56: Packing and shipping Marks:
B57: (8)装运期
B58: Time of Shipment: | C58: =TODAY()+15 -> 46170 | F58: 之前
B59: (9)装运口岸和目的地 深圳--- | E59: =箱单!E7 -> 英国 | F59: 准许分批与转船。
B61: (10)保险：由买方按发票全部金额110%投保至 为止的 险。按中国海洋运输保险条款为理。
B62: Insurance:To be covered by the Buyer for 110% of full invoice value covering up to only,subject to C.I.C.
...

Sheet 委托书
E3: 代 理 报 关 委 托 书
G5: 编号：□□□□□□□□□□□
C6: =报关单!V11 -> 0
B7: 我单位现 A (A逐票、B长期)委托贵公司代理 AB 等通关事宜。（A、填单申报 B、辅助查验 C、
B8: 垫缴税款 D、办理海关证明联 E、审批手册 F、核销手册 G、申办减免税手续 H、其他 ）详见《委托报关协
B9: 议》。
B10: 我单位保证遵守《海关法》和国家有关法规，保证所提供的情况真实、完整、单货相符，无侵犯他
B11: 人知识产权的行为。否则，愿承担相关法律责任。
B12: 本委托书有效期自签字之日起至 | E12: 20 年 月 日止。
G13: 委托方（盖章）：
D15: 法定代表人或其授权签署《代理报关委托书》的人（签字）
H16: =TODAY()-1 -> 46154
E18: 委 托 报 关 协 议
B20: 为明确委托报关具体事项和各自责任，双方经平等协商签定协议如下：
B21: 委托方 | C21: =报关单!A4 -> 深圳市新棱镜贸易有限公司 | G21: 被委托方 | H21: =报关单!Y11 -> 0
B22: 主要货物名称 | C22: =报关单!D20 -> 编织表带 | G22: *报关单编码
B23: HS编码 | C23: =报关单!B20 -> 9113900090 | G23: 收到单证日期 | H23: =TODAY() -> 46155
B24: 货物总价 | C24: =发票!H55 -> 人民币 | D24: =发票!I55 -> 24985 | G24: 收到单证情况 | H24: 合同□√ | I24: 发票□√
B25: 进出口日期 | C25: =TODAY()+1 -> 46156 | H25: 装箱清单□√ | I25: 提（运）单□
B26: 提单号 | H26: 加工贸易手册□ | I26: 许可证件□
B27: 贸易方式 | C27: =报关单!E8 -> 一般贸易 | H27: 其他
B28: 原产地/货源地 | C28: =报关单!P20 -> 深圳特区 | G28: 报关收费 | H28: 人民币： 元
B29: 其他要求： | G29: 承诺说明：
B36: 背面所列通用条款是本协议不可分割的一部分，对本协议的签署构成了对背面通用条款的同意。 | G36: 背面所列通用条款是本协议不可分割的一部分，对本协议的签署构成了对背面通用条款的同意。
B39: 委托方业务签章： | G39: 被委托方业务签章：
B44: 经办人签章： | G44: 经办报关员签章：
B45: 联系电话： | E45: =TODAY() -> 46155 | G45: 联系电话： | I45: =TODAY() -> 46155
C48: （白联：海关留存、黄联：被委托方留存、红联：委托方留存） | I48: 中国报关协会监制
